<sdf version='1.6'>
  <world name='default'>
    <light name='sun' type='directional'>
      <cast_shadows>1</cast_shadows>
      <pose frame=''>0 0 10 0 -0 0</pose>
      <diffuse>0.8 0.8 0.8 1</diffuse>
      <specular>0.1 0.1 0.1 1</specular>
      <attenuation>
        <range>1000</range>
        <constant>0.9</constant>
        <linear>0.01</linear>
        <quadratic>0.001</quadratic>
      </attenuation>
      <direction>-0.5 0.5 -1</direction>
    </light>
    <model name='ground_plane'>
      <static>1</static>
      <link name='link'>
        <collision name='collision'>
          <geometry>
            <plane>
              <normal>0 0 1</normal>
              <size>100 100</size>
            </plane>
          </geometry>
          <surface>
            <friction>
              <ode>
                <mu>100</mu>
                <mu2>50</mu2>
              </ode>
              <torsional>
                <ode/>
              </torsional>
            </friction>
            <contact>
              <ode/>
            </contact>
            <bounce/>
          </surface>
          <max_contacts>10</max_contacts>
        </collision>
        <visual name='visual'>
          <cast_shadows>0</cast_shadows>
          <geometry>
            <plane>
              <normal>0 0 1</normal>
              <size>100 100</size>
            </plane>
          </geometry>
          <material>
            <script>
              <uri>file://media/materials/scripts/gazebo.material</uri>
              <name>Gazebo/Grey</name>
            </script>
          </material>
        </visual>
        <self_collide>0</self_collide>
        <kinematic>0</kinematic>
        <gravity>1</gravity>
      </link>
    </model>
    <gravity>0 0 -9.8</gravity>
    <magnetic_field>6e-06 2.3e-05 -4.2e-05</magnetic_field>
    <atmosphere type='adiabatic'/>
    <physics name='default_physics' default='0' type='ode'>
      <max_step_size>0.001</max_step_size>
      <real_time_factor>1</real_time_factor>
      <real_time_update_rate>1000</real_time_update_rate>
    </physics>
    <scene>
      <ambient>0.4 0.4 0.4 1</ambient>
      <background>0.7 0.7 0.7 1</background>
      <shadows>1</shadows>
    </scene>
    <spherical_coordinates>
      <surface_model>EARTH_WGS84</surface_model>
      <latitude_deg>0</latitude_deg>
      <longitude_deg>0</longitude_deg>
      <elevation>0</elevation>
      <heading_deg>0</heading_deg>
    </spherical_coordinates>
    <model name='unit_box_1_clone_clone'>
      <pose frame=''>-0.457467 3.35738 1.58591 2.5e-05 2e-06 -1.56645</pose>
      <link name='link'>
        <inertial>
          <mass>1</mass>
          <inertia>
            <ixx>0.166667</ixx>
            <ixy>0</ixy>
            <ixz>0</ixz>
            <iyy>0.166667</iyy>
            <iyz>0</iyz>
            <izz>0.166667</izz>
          </inertia>
        </inertial>
        <collision name='collision'>
          <geometry>
            <box>
              <size>0.769515 4.03056 3.17193</size>
            </box>
          </geometry>
          <max_contacts>10</max_contacts>
          <surface>
            <contact>
              <ode/>
            </contact>
            <bounce/>
            <friction>
              <torsional>
                <ode/>
              </torsional>
              <ode/>
            </friction>
          </surface>
        </collision>
        <visual name='visual'>
          <geometry>
            <box>
              <size>0.769515 4.03056 3.17193</size>
            </box>
          </geometry>
          <material>
            <script>
              <name>Gazebo/Grey</name>
              <uri>file://media/materials/scripts/gazebo.material</uri>
            </script>
          </material>
        </visual>
        <self_collide>0</self_collide>
        <kinematic>0</kinematic>
        <gravity>1</gravity>
      </link>
    </model>
    <model name='unit_box_1_clone_clone_clone'>
      <pose frame=''>-4.02431 -0.001059 1.58591 -2.6e-05 -2e-06 -1.57046</pose>
      <link name='link'>
        <inertial>
          <mass>1</mass>
          <inertia>
            <ixx>0.166667</ixx>
            <ixy>0</ixy>
            <ixz>0</ixz>
            <iyy>0.166667</iyy>
            <iyz>0</iyz>
            <izz>0.166667</izz>
          </inertia>
        </inertial>
        <collision name='collision'>
          <geometry>
            <box>
              <size>0.769516 4.03056 3.17193</size>
            </box>
          </geometry>
          <max_contacts>10</max_contacts>
          <surface>
            <contact>
              <ode/>
            </contact>
            <bounce/>
            <friction>
              <torsional>
                <ode/>
              </torsional>
              <ode/>
            </friction>
          </surface>
        </collision>
        <visual name='visual'>
          <geometry>
            <box>
              <size>0.769516 4.03056 3.17193</size>
            </box>
          </geometry>
          <material>
            <script>
              <name>Gazebo/Grey</name>
              <uri>file://media/materials/scripts/gazebo.material</uri>
            </script>
          </material>
        </visual>
        <self_collide>0</self_collide>
        <kinematic>0</kinematic>
        <gravity>1</gravity>
      </link>
    </model>
    <model name='unit_box_1_clone_clone_clone_clone'>
      <pose frame=''>2.40055 0.298961 1.58359 0.000717 -2e-05 3.14024</pose>
      <link name='link'>
        <inertial>
          <mass>1</mass>
          <inertia>
            <ixx>0.166667</ixx>
            <ixy>0</ixy>
            <ixz>0</ixz>
            <iyy>0.166667</iyy>
            <iyz>0</iyz>
            <izz>0.166667</izz>
          </inertia>
        </inertial>
        <collision name='collision'>
          <geometry>
            <box>
              <size>0.43682 6.65632 3.17193</size>
            </box>
          </geometry>
          <max_contacts>10</max_contacts>
          <surface>
            <contact>
              <ode/>
            </contact>
            <bounce/>
            <friction>
              <torsional>
                <ode/>
              </torsional>
              <ode/>
            </friction>
          </surface>
        </collision>
        <visual name='visual'>
          <geometry>
            <box>
              <size>0.43682 6.65632 3.17193</size>
            </box>
          </geometry>
          <material>
            <script>
              <name>Gazebo/Grey</name>
              <uri>file://media/materials/scripts/gazebo.material</uri>
            </script>
          </material>
        </visual>
        <self_collide>0</self_collide>
        <kinematic>0</kinematic>
        <gravity>1</gravity>
      </link>
    </model>
    <model name='unit_box_1_clone_clone_clone_clone_clone'>
      <pose frame=''>-2.77503 -0.10406 1.58311 0.000859 -2e-06 -3.13944</pose>
      <link name='link'>
        <inertial>
          <mass>1</mass>
          <inertia>
            <ixx>0.166667</ixx>
            <ixy>0</ixy>
            <ixz>0</ixz>
            <iyy>0.166667</iyy>
            <iyz>0</iyz>
            <izz>0.166667</izz>
          </inertia>
        </inertial>
        <collision name='collision'>
          <geometry>
            <box>
              <size>1.3556 6.65632 3.17193</size>
            </box>
          </geometry>
          <max_contacts>10</max_contacts>
          <surface>
            <contact>
              <ode/>
            </contact>
            <bounce/>
            <friction>
              <torsional>
                <ode/>
              </torsional>
              <ode/>
            </friction>
          </surface>
        </collision>
        <visual name='visual'>
          <geometry>
            <box>
              <size>1.3556 6.65632 3.17193</size>
            </box>
          </geometry>
          <material>
            <script>
              <name>Gazebo/Grey</name>
              <uri>file://media/materials/scripts/gazebo.material</uri>
            </script>
          </material>
        </visual>
        <self_collide>0</self_collide>
        <kinematic>0</kinematic>
        <gravity>1</gravity>
      </link>
    </model>
    <state world_name='default'>
      <sim_time>2472 39000000</sim_time>
      <real_time>1986 607169226</real_time>
      <wall_time>1514298460 25915598</wall_time>
      <iterations>1980247</iterations>
      <model name='ground_plane'>
        <pose frame=''>0 0 0 0 -0 0</pose>
        <scale>1 1 1</scale>
        <link name='link'>
          <pose frame=''>0 0 0 0 -0 0</pose>
          <velocity>0 0 0 0 -0 0</velocity>
          <acceleration>0 0 0 0 -0 0</acceleration>
          <wrench>0 0 0 0 -0 0</wrench>
        </link>
      </model>
      <model name='spinning_lidar'>
        <pose frame=''>0 0 0 0 -0 0</pose>
        <scale>1 1 1</scale>
        <link name='laser_axis'>
          <pose frame=''>0.035 0 0.135 -0.612016 0 0</pose>
          <velocity>0 0 0 0 -0 0</velocity>
          <acceleration>0 0 0 0 -0 0</acceleration>
          <wrench>0 0 0 0 -0 0</wrench>
        </link>
        <link name='laser_mount_base_link'>
          <pose frame=''>0 0 0 0 -0 0</pose>
          <velocity>0 0 0 0 -0 0</velocity>
          <acceleration>0 0 0 0 -0 0</acceleration>
          <wrench>0 0 0 0 -0 0</wrench>
        </link>
      </model>
      <model name='unit_box_1_clone_clone'>
        <pose frame=''>-0.084636 2.80477 1.58591 2.6e-05 -2e-06 -1.56308</pose>
        <scale>1 1 1</scale>
        <link name='link'>
          <pose frame=''>-0.084636 2.80477 1.58591 2.6e-05 -2e-06 -1.56308</pose>
          <velocity>0 0 0 0 -0 0</velocity>
          <acceleration>-9.79999 0.663492 -1.4e-05 -1.70513 -0.170819 -1.3e-05</acceleration>
          <wrench>-9.79999 0.663492 -1.4e-05 0 -0 0</wrench>
        </link>
      </model>
      <model name='unit_box_1_clone_clone_clone'>
        <pose frame=''>-0.077337 -3.16349 1.58591 2.5e-05 2e-06 -1.55447</pose>
        <scale>1 1 1</scale>
        <link name='link'>
          <pose frame=''>-0.077337 -3.16349 1.58591 2.5e-05 2e-06 -1.55447</pose>
          <velocity>0 0 0 0 -0 0</velocity>
          <acceleration>-9.79998 -0.874659 -2.2e-05 2.25852 0.051439 1.6e-05</acceleration>
          <wrench>-9.79998 -0.874659 -2.2e-05 0 -0 0</wrench>
        </link>
      </model>
      <model name='unit_box_1_clone_clone_clone_clone'>
        <pose frame=''>2.63879 -0.123337 1.58311 -0.000859 2e-06 -3.13944</pose>
        <scale>1.76163 1 1</scale>
        <link name='link'>
          <pose frame=''>2.63879 -0.123337 1.58311 -0.000859 2e-06 -3.13944</pose>
          <velocity>0 -0.004668 -0.159873 0.051097 1e-06 0</velocity>
          <acceleration>0.000546 -9.8 0 1.66206 0.001278 0</acceleration>
          <wrench>0.000546 -9.8 0 0 -0 0</wrench>
        </link>
      </model>
      <model name='unit_box_1_clone_clone_clone_clone_clone'>
        <pose frame=''>-2.8053 -0.054739 1.58311 0.000859 -2e-06 -3.13944</pose>
        <scale>1 1 1</scale>
        <link name='link'>
          <pose frame=''>-2.8053 -0.054739 1.58311 0.000859 -2e-06 -3.13944</pose>
          <velocity>0 0.007593 -0.159873 -0.051097 0 0</velocity>
          <acceleration>-0.000546 9.8 0 -1.66206 -0.001278 0</acceleration>
          <wrench>-0.000546 9.8 0 0 -0 0</wrench>
        </link>
      </model>
      <light name='sun'>
        <pose frame=''>0 0 10 0 -0 0</pose>
      </light>
    </state>
    <gui fullscreen='0'>
      <camera name='user_camera'>
        <pose frame=''>-13.2824 -1.6716 11.9331 0 0.813798 0.3282</pose>
        <view_controller>orbit</view_controller>
        <projection_type>perspective</projection_type>
      </camera>
    </gui>
    <model name='spinning_lidar'>
      <link name='laser_mount_base_link'>
        <pose frame=''>0 0 0 0 -0 0</pose>
        <inertial>
          <pose frame=''>0 0 0.075 0 -0 0</pose>
          <mass>0.15</mass>
          <inertia>
            <ixx>0.036125</ixx>
            <ixy>0</ixy>
            <ixz>0</ixz>
            <iyy>0.030125</iyy>
            <iyz>0</iyz>
            <izz>0.01</izz>
          </inertia>
        </inertial>
        <collision name='laser_mount_base_link_fixed_joint_lump__collision_collision'>
          <pose frame=''>0 0 0.075 0 -0 0</pose>
          <geometry>
            <box>
              <size>0.04 0.08 0.15</size>
            </box>
          </geometry>
          <max_contacts>10</max_contacts>
          <surface>
            <contact>
              <ode/>
            </contact>
            <bounce/>
            <friction>
              <torsional>
                <ode/>
              </torsional>
              <ode/>
            </friction>
          </surface>
        </collision>
        <visual name='laser_mount_base_link_fixed_joint_lump__visual_visual'>
          <pose frame=''>0 0 0.075 0 -0 0</pose>
          <geometry>
            <box>
              <size>0.04 0.08 0.15</size>
            </box>
          </geometry>
        </visual>
        <gravity>1</gravity>
        <velocity_decay/>
        <self_collide>0</self_collide>
        <gravity>1</gravity>
        <kinematic>0</kinematic>
      </link>
      <joint name='laser_base_link_to_parent' type='revolute'>
        <child>laser_mount_base_link</child>
        <parent>world</parent>
        <axis>
          <limit>
            <lower>0</lower>
            <upper>0</upper>
          </limit>
          <dynamics>
            <damping>0</damping>
            <friction>0</friction>
            <spring_reference>0</spring_reference>
            <spring_stiffness>0</spring_stiffness>
          </dynamics>
          <use_parent_model_frame>1</use_parent_model_frame>
          <xyz>0 0 1</xyz>
        </axis>
      </joint>
      <link name='laser_axis'>
        <pose frame=''>0.035 0 0.135 0 -0 0</pose>
        <inertial>
          <pose frame=''>0.019783 0 0.01413 0 -0 0</pose>
          <mass>0.23</mass>
          <inertia>
            <ixx>0.0243353</ixx>
            <ixy>0</ixy>
            <ixz>-4.94565e-05</ixz>
            <iyy>0.0204046</iyy>
            <iyz>0</iyz>
            <izz>0.00695257</izz>
          </inertia>
        </inertial>
        <collision name='laser_axis_fixed_joint_lump__laser_collision'>
          <pose frame=''>0.035 0 0.0135 0 -0 0</pose>
          <geometry>
            <box>
              <size>0.05 0.05 0.07</size>
            </box>
          </geometry>
          <surface>
            <contact>
              <ode/>
            </contact>
            <friction>
              <ode/>
              <torsional>
                <ode/>
              </torsional>
            </friction>
            <bounce/>
          </surface>
          <max_contacts>10</max_contacts>
        </collision>
        <visual name='laser_axis_fixed_joint_lump__visual_visual'>
          <pose frame=''>0 0 0 3.14159 1.57079 3.14159</pose>
          <geometry>
            <cylinder>
              <length>0.035</length>
              <radius>0.02</radius>
            </cylinder>
          </geometry>
        </visual>
        <visual name='laser_axis_fixed_joint_lump__laser_visual_1'>
          <pose frame=''>0.035 0 0.025 0 -0 0</pose>
          <geometry>
            <mesh>
              <scale>1 1 1</scale>
              <uri>/home/yumisummer/Yoshua/DD2465_ws/src/spinning_lidar/spinning_lidar_description/meshes/LIDAR/hokuyo_ust_10lx.stl</uri>
            </mesh>
          </geometry>
          <material>
            <script>
              <name>Gazebo/DarkGrey</name>
              <uri>file://media/materials/scripts/gazebo.material</uri>
            </script>
          </material>
        </visual>
        <gravity>1</gravity>
        <velocity_decay/>
        <self_collide>0</self_collide>
        <sensor name='lidar_sensor' type='ray'>
          <visualize>0</visualize>
          <always_on>1</always_on>
          <update_rate>40</update_rate>
          <ray>
            <scan>
              <horizontal>
                <samples>1080</samples>
                <resolution>1</resolution>
                <min_angle>-2.35619</min_angle>
                <max_angle>2.35619</max_angle>
              </horizontal>
              <vertical>
                <samples>1</samples>
                <min_angle>0</min_angle>
                <max_angle>0</max_angle>
              </vertical>
            </scan>
            <range>
              <min>0.08</min>
              <max>60</max>
              <resolution>0.01</resolution>
            </range>
            <noise>
              <type>gaussian</type>
              <mean>0</mean>
              <stddev>0.004</stddev>
            </noise>
          </ray>
          <plugin name='gazebo_ros_hokuyo_ust_20lx_gazebo' filename='libgazebo_ros_laser.so'>
            <topicName>spinning_lidar/scan</topicName>
            <frameName>laser</frameName>
            <robotNamespace>/</robotNamespace>
          </plugin>
          <pose frame=''>0.035 0 0.025 0 -0 0</pose>
        </sensor>
        <kinematic>0</kinematic>
      </link>
      <joint name='lidar_spin_joint' type='revolute'>
        <child>laser_axis</child>
        <parent>laser_mount_base_link</parent>
        <axis>
          <xyz>1 0 0</xyz>
          <limit>
            <lower>-1e+16</lower>
            <upper>1e+16</upper>
          </limit>
          <dynamics>
            <spring_reference>0</spring_reference>
            <spring_stiffness>0</spring_stiffness>
          </dynamics>
          <use_parent_model_frame>1</use_parent_model_frame>
        </axis>
      </joint>
      <plugin name='ir_interrupt_plugin' filename='libir_interrupt_plugin.so'>
        <joint>lidar_spin_joint</joint>
        <half_cycle_int>true</half_cycle_int>
        <angle_tol>0.02</angle_tol>
        <robotNamespace>/</robotNamespace>
      </plugin>
      <static>0</static>
      <plugin name='spinning_lidar_gazebo_ros_control' filename='libgazebo_ros_control.so'>
        <robotNamespace>/spinning_lidar</robotNamespace>
      </plugin>
      <pose frame=''>0 0 0 0 -0 0</pose>
    </model>
  </world>
</sdf>
